Workbook

Sheet Computational resources
A1: COMPUTATIONAL RESOURCES
A2: Metric | B2: GATK | C2: DeepVariant | D2: DRAGEN-GATK
A3: Wall clock time | B3: 81,63 h | C3: 10,55 h | D3: 119,57 h
A4: CPU utilisation | B4: 0.9933 | C4: 0.9994 | D4: 0.979
A5: CPU time | B5: 81,15 h | C5: 12,42 h | D5: 117,04 h
A6: Peak memory (RAM) | B6: 4,60 GB | C6: 108,85 GB | D6: 10,39 GB
A8: Call set | B8: Final jVCF | C8: Samples
A9: GATK | B9: gatk_hardfiltered_PASS.vcf.gz | C9: 44
A10: DeepVariant | B10: deepvariant_joint.vcf.gz | C10: 44
A11: DRAGEN-GATK | B11: dragen_gatk_hardfiltered_PASS.vcf.gz | C11: 44

Sheet Variant Counts
A1: VARIANT COUNTS & CALLSET QUALITY
A3: Metric | B3: GATK | C3: DeepVariant | D3: DRAGEN-GATK
A4: Total variants | B4: 24097372 | C4: 24008026 | D4: 24031511
A5: SNPs | B5: 20635443 | C5: 20967444 | D5: 20597410
A6: INDELS | B6: 3461929 | C6: 3281708 | D6: 3434101
A7: SNP/INDEL ratio | B7: =B5/B6 -> 5.9606777 | C7: =C5/C6 -> 6.3891864 | D7: =D5/D6 -> 5.9979045
A8: Multiallelic variant | B8: 1382916 | C8: 1066391 | D8: 1373812
A9: Biallelic variant | B9: 22714456 | C9: 22941635 | D9: 22657699
A10: Ti/Tv ratio — overall | B10: 2.05 | C10: 2.04 | D10: 2.06
A11: Ti/Tv — known variants | B11: 2.130963 | C11: 2.111126 | D11: 2.131821
A12: Ti/Tv — novel variants | B12: 1.603994 | C12: 1.802955 | D12: 1.617164
A13: Het/hom ratio | B13: 2.1845 | C13: 1.8873 | D13: 2.0448
A14: Hardy-Weinberg deviation (%) | B14: 0.004395 | C14: 0.003449 | D14: 0.002419
A15: HWE-deviant sites (P<10^-6) | B15: 117935 | C15: 91457 | D15: 64815
A16: Multiallelic % | B16: =B8/B4 -> 0.057388665 | C16: =C8/C4 -> 0.044418104 | D16: =D8/D4 -> 0.057167109

Sheet Database Con & Variant
A1: DATABASE CONCORDANCE AND VARIANT NOVELTY
A3: Metric | B3: GATK | C3: DeepVariant | D3: DRAGEN-GATK
A4: dbSNP concordance rate | B4: 0.5993 | C4: 0.6124 | D4: 0.5995
A5: gnomAD — common variants MAF ≥ 0.05 in gnomAD | B5: 0.394 | C5: 0.44 | D5: 0.428
A6: gnomAD — rare variants MAF < 0.05 in gnomAD | B6: 0.518 | C6: 0.5 | D6: 0.5
A7: Novel variant rate Absent from gnomAD entirely | B7: 0.08 | C7: 0.06 | D7: 0.064
A8: 3-caller overlap | B8: 24671010 | C8: 24671010 | D8: 24671010
A9: Caller-unique variants | B9: 310853 | C9: 1556468 | D9: 293040
A10: Primary-chromosome SNPs | B10: 15903958 known + 4876823 novel | C10: 16218254 known + 4837121 novel | D10: 15887245 known + 4871392 novel
A11: Known SNPs | B11: 15903958 | C11: 16218254 | D11: 15887245
A12: Novel SNPs | B12: 4876823 | C12: 4837121 | D12: 4871392
A13: dbSNP-known variants | B13: 15909438 | C13: 16223925 | D13: 15892719
A14: dbSNP-known rate | B14: =B13/(B13+B15) -> 0.59932829 | C14: =C13/(C13+C15) -> 0.6124099 | D14: =D13/(D13+D15) -> 0.59947245
A15: Novel / absent from dbSNP | B15: 10636010 | C15: 10268013 | D15: 10618456
A16: Novel rate | B16: =B15/(B13+B15) -> 0.40067171 | C16: =C15/(C13+C15) -> 0.3875901 | D16: =D15/(D13+D15) -> 0.40052755
A19: Pairwise concordance | B19: Shared variants | C19: Union | D19: Jaccard
A20: GATK vs DeepVariant | B20: 24811470 | C20: 28225916 | D20: 0.87903153
A21: GATK vs DRAGEN-GATK | B21: 26094135 | C21: 26962488 | D21: 0.96779403
A22: DeepVariant vs DRAGEN-GATK | B22: 24795010 | C22: 28208103 | D22: 0.8790031

Sheet gnomAD AF_grpmax
A1: GNOMAD v4.1 AF_grpmax CLASSES, PASS-ONLY, FULL CALL SETS (ALLELES)
A3: Metric | B3: GATK | C3: DeepVariant | D3: DRAGEN-GATK
A4: All alleles (chr1-22, X; PASS-only)
A5: Novel (AF_grpmax missing or not in gnomAD) | B5: 1514600 | C5: 1612543 | D5: 1538680
A6: Rare (0 < AF_grpmax < 0.05) | B6: 11443263 | C6: 11359705 | D6: 11418129
A7: Common (AF_grpmax ≥ 0.05) | B7: 13101459 | C7: 13378478 | D7: 13071221
A8: Total classified | B8: =SUM(B5:B7) -> 26059322 | C8: =SUM(C5:C7) -> 26350726 | D8: =SUM(D5:D7) -> 26028030
A9: Novel (%) | B9: =B5/B8 -> 0.058121236 | C9: =C5/C8 -> 0.061195392 | D9: =D5/D8 -> 0.059116268
A10: Rare (%) | B10: =B6/B8 -> 0.43912359 | C10: =C6/C8 -> 0.43109647 | D10: =D6/D8 -> 0.43868587
A11: Common (%) | B11: =B7/B8 -> 0.50275518 | C11: =C7/C8 -> 0.50770814 | D11: =D7/D8 -> 0.50219786
A13: Alleles excluded from the classification
A14: Other contigs (alternate, decoy, unplaced, chrY, chrM) | B14: 291175 | C14: 39717 | D14: 256954
A15: Spanning-deletion (*) alleles | B15: 438406 | C15: 0 | D15: 434603
A16: OTHER-type alleles | B16: 0 | C16: 1594 | D16: 0
A17: No carrier in any sample (AC = 0) | B17: 0 | C17: 0 | D17: 1
A18: Total excluded | B18: =SUM(B14:B17) -> 729581 | C18: =SUM(C14:C17) -> 41311 | D18: =SUM(D14:D17) -> 691558
A19: Total alleles in the split call set | B19: 26788903 | C19: 26392037 | D19: 26719588
A20: Check: classified + excluded − total | B20: =B8+B18-B19 -> 0 | C20: =C8+C18-C19 -> 0 | D20: =D8+D18-D19 -> 0
A22: SAC (n=39)
A23: Novel | B23: 1419634 | C23: 1518980 | D23: 1438266
A24: Rare | B24: 10610872 | C24: 10510895 | D24: 10585522
A25: Common | B25: 12980228 | C25: 13249189 | D25: 12949853
A26: Total alleles present in group | B26: =SUM(B23:B25) -> 25010734 | C26: =SUM(C23:C25) -> 25279064 | D26: =SUM(D23:D25) -> 24973641
A27: Novel (%) | B27: =B23/B26 -> 0.056760989 | C27: =C23/C26 -> 0.060088459 | D27: =D23/D26 -> 0.057591362
A28: Rare (%) | B28: =B24/B26 -> 0.42425272 | C28: =C24/C26 -> 0.41579447 | D28: =D24/D26 -> 0.42386779
A29: Common (%) | B29: =B25/B26 -> 0.51898629 | C29: =C25/C26 -> 0.52411707 | D29: =D25/D26 -> 0.51854085
A31: European (n=2)
A32: Novel | B32: 45241 | C32: 76585 | D32: 42996
A33: Rare | B33: 412628 | C33: 344089 | D33: 408852
A34: Common | B34: 5922079 | C34: 5910792 | D34: 5898528
A35: Total alleles present in group | B35: =SUM(B32:B34) -> 6379948 | C35: =SUM(C32:C34) -> 6331466 | D35: =SUM(D32:D34) -> 6350376
A36: Novel (%) | B36: =B32/B35 -> 0.0070911236 | C36: =C32/C35 -> 0.012095935 | D36: =D32/D35 -> 0.0067706227
A37: Rare (%) | B37: =B33/B35 -> 0.064675762 | C37: =C33/C35 -> 0.054345866 | D37: =D33/D35 -> 0.064382329
A38: Common (%) | B38: =B34/B35 -> 0.92823311 | C38: =C34/C35 -> 0.9335582 | D38: =D34/D35 -> 0.92884705
A40: African (n=3)
A41: Novel | B41: 161364 | C41: 199409 | D41: 159547
A42: Rare | B42: 1994472 | C42: 1938876 | D42: 1986334
A43: Common | B43: 7915319 | C43: 7967949 | D43: 7890038
A44: Total alleles present in group | B44: =SUM(B41:B43) -> 10071155 | C44: =SUM(C41:C43) -> 10106234 | D44: =SUM(D41:D43) -> 10035919
A45: Novel (%) | B45: =B41/B44 -> 0.016022393 | C45: =C41/C44 -> 0.019731287 | D45: =D41/D44 -> 0.015897597
...

Sheet Allele AF bins
A1: COHORT ALLELE FREQUENCY BINS (n=44, ALLELE LEVEL)
A3: Metric | B3: GATK | C3: DeepVariant | D3: DRAGEN-GATK
A4: Common (AF ≥ 0.05) | B4: 11584295 | C4: 11564214 | D4: 11708766
A5: Low-frequency (0.02 ≤ AF < 0.05) | B5: 6734417 | C5: 6441887 | D5: 6569340
A6: Rare (0.01 ≤ AF < 0.02) | B6: 8470191 | C6: 8486755 | D6: 8441481
A7: Below 0.01 | B7: 0 | C7: 0 | D7: 1
A8: Total alleles after splitting | B8: =SUM(B4:B7) -> 26788903 | C8: =SUM(C4:C7) -> 26492856 | D8: =SUM(D4:D7) -> 26719588
A9: Records (Variant Counts) | B9: ='Variant Counts'!B4 -> 24097372 | C9: ='Variant Counts'!C4 -> 24008026 | D9: ='Variant Counts'!D4 -> 24031511
A10: Extra alleles from multiallelic splitting | B10: =B8-B9 -> 2691531 | C10: =C8-C9 -> 2484830 | D10: =D8-D9 -> 2688077
A11: Multiallelic records split | B11: ='Variant Counts'!B8 -> 1382916 | C11: ='Variant Counts'!C8 -> 1066391 | D11: ='Variant Counts'!D8 -> 1373812
A12: Common (%) | B12: =B4/B8 -> 0.43242887 | C12: =C4/C8 -> 0.43650311 | D12: =D4/D8 -> 0.43820908
A13: Low-frequency (%) | B13: =B5/B8 -> 0.25138831 | C13: =C5/C8 -> 0.24315563 | D13: =D5/D8 -> 0.24586232
A14: Rare (%) | B14: =B6/B8 -> 0.31618282 | C14: =C6/C8 -> 0.32034126 | D14: =D6/D8 -> 0.31592856
A15: Below 0.01 (%) | B15: =B7/B8 -> 0 | C15: =C7/C8 -> 0 | D15: =D7/D8 -> 3.7425727e-08
A16: SNP alleles | B16: 20725809 | C16: 21055835 | D16: 20684958
A17: INDEL alleles | B17: 5613978 | C17: 5435123 | D17: 5590851
A18: Spanning-deletion (OVERLAP) alleles | B18: 449116 | C18: 0 | D18: 443779
A19: OTHER alleles | B19: 0 | C19: 1898 | D19: 0

Sheet Pop Metrics - DeepVariant
A1: POPULATION METRICS — DeepVariant + Glnexus
A3: Metric | B3: African (n=3) | C3: European (n=2) | D3: SAC (n=39)
A4: Samples | B4: 3 | C4: 2 | D4: 39
A5: Total variants | B5: 24008026 | C5: 24008026 | D5: 24008026
A6: SNPs | B6: 20967444 | C6: 20967444 | D6: 20967444
A7: INDELs | B7: 3281708 | C7: 3281708 | D7: 3281708
A8: SNP/INDEL ratio | B8: =IFERROR(B6/B7,"") -> 6.3891864 | C8: =IFERROR(C6/C7,"") -> 6.3891864 | D8: =IFERROR(D6/D7,"") -> 6.3891864
A9: Multiallelic | B9: 1066391 | C9: 1066391 | D9: 1066391
A10: Multiallelic % | B10: =IFERROR(B9/B5,"") -> 0.044418104 | C10: =IFERROR(C9/C5,"") -> 0.044418104 | D10: =IFERROR(D9/D5,"") -> 0.044418104
A11: Biallelic | B11: 22941635 | C11: 22941635 | D11: 22941635
A12: Ti/Tv | B12: 2.04 | C12: 2.04 | D12: 2.04
A13: Total genotypes | B13: =SUM(B14:B18) -> 72024078 | C13: =SUM(C14:C18) -> 48016052 | D13: =SUM(D14:D18) -> 936313014
A14: Missing genotypes | B14: 1270676 | C14: 799582 | D14: 16400614
A15: HOM_REF | B15: 53755678 | C15: 38075933 | D15: 714273212
A16: HET | B16: 11198249 | C16: 5563801 | D16: 136482836
A17: HOM_ALT | B17: 5698705 | C17: 3530866 | D17: 68017925
A18: Other genotypes | B18: 100770 | C18: 45870 | D18: 1138427
A19: Missingness | B19: =B14/B13 -> 0.017642378 | C19: =C14/C13 -> 0.016652389 | D19: =D14/D13 -> 0.017516166
A20: HET/HOM_ALT ratio | B20: =B16/B17 -> 1.9650515 | C20: =C16/C17 -> 1.575761 | D20: =D16/D17 -> 2.0065716

Sheet Pop Metrics - GATK
A1: POPULATION METRICS — GATK
A3: Metric | B3: African (n=3) | C3: European (n=2) | D3: SAC (n=39)
A4: Samples | B4: 3 | C4: 2 | D4: 39
A5: Total variants | B5: 24097372 | C5: 24097372 | D5: 24097372
A6: SNPs | B6: 20635443 | C6: 20635443 | D6: 20635443
A7: INDELs | B7: 3461929 | C7: 3461929 | D7: 3461929
A8: SNP/INDEL ratio | B8: =IFERROR(B6/B7,"") -> 5.9606777 | C8: =IFERROR(C6/C7,"") -> 5.9606777 | D8: =IFERROR(D6/D7,"") -> 5.9606777
A9: Multiallelic | B9: 1382916 | C9: 1382916 | D9: 1382916
A10: Multiallelic % | B10: =IFERROR(B9/B5,"") -> 0.057388665 | C10: =IFERROR(C9/C5,"") -> 0.057388665 | D10: =IFERROR(D9/D5,"") -> 0.057388665
A11: Biallelic | B11: 22714456 | C11: 22714456 | D11: 22714456
A12: Ti/Tv | B12: 2.05 | C12: 2.05 | D12: 2.05
A13: Total genotypes | B13: =SUM(B14:B18) -> 72292116 | C13: =SUM(C14:C18) -> 48194744 | D13: =SUM(D14:D18) -> 939797508
A14: Missing genotypes | B14: 665 | C14: 291 | D14: 7169
A15: HOM_REF | B15: 54932987 | C15: 38776749 | D15: 729210822
A16: HET | B16: 11816353 | C16: 6038050 | D16: 144956628
A17: HOM_ALT | B17: 5541244 | C17: 3379142 | D17: 65611410
A18: Other genotypes | B18: 867 | C18: 512 | D18: 11479
A19: Missingness | B19: =B14/B13 -> 9.1987901e-06 | C19: =C14/C13 -> 6.0380028e-06 | D19: =D14/D13 -> 7.628239e-06
A20: HET/HOM_ALT ratio | B20: =B16/B17 -> 2.1324369 | C20: =C16/C17 -> 1.7868589 | D20: =D16/D17 -> 2.2093204

Sheet Pop Metrics - DRAGEN-GATK
A1: POPULATION METRICS — DRAGEN-GATK
A3: Metric | B3: African (n=3) | C3: European (n=2) | D3: SAC (n=39)
A4: Samples | B4: 3 | C4: 2 | D4: 39
A5: Total variants | B5: 24031511 | C5: 24031511 | D5: 24031511
A6: SNPs | B6: 20597410 | C6: 20597410 | D6: 20597410
A7: INDELs | B7: 3434101 | C7: 3434101 | D7: 3434101
A8: SNP/INDEL ratio | B8: =IFERROR(B6/B7,"") -> 5.9979045 | C8: =IFERROR(C6/C7,"") -> 5.9979045 | D8: =IFERROR(D6/D7,"") -> 5.9979045
A9: Multiallelic | B9: 1373812 | C9: 1373812 | D9: 1373812
A10: Multiallelic % | B10: =IFERROR(B9/B5,"") -> 0.057167109 | C10: =IFERROR(C9/C5,"") -> 0.057167109 | D10: =IFERROR(D9/D5,"") -> 0.057167109
A11: Biallelic | B11: 22657699 | C11: 22657699 | D11: 22657699
A12: Ti/Tv | B12: 2.06 | C12: 2.06 | D12: 2.06
A13: Total genotypes | B13: =SUM(B14:B18) -> 72094533 | C13: =SUM(C14:C18) -> 48063022 | D13: =SUM(D14:D18) -> 937228929
A14: Missing genotypes | B14: 873260 | C14: 477375 | D14: 11067092
A15: HOM_REF | B15: 53983136 | C15: 38242601 | D15: 717185682
A16: HET | B16: 11702382 | C16: 5965912 | D16: 143434101
A17: HOM_ALT | B17: 5535755 | C17: 3377134 | D17: 65542054
A18: Other genotypes | B18: 0 | C18: 0 | D18: 0
A19: Missingness | B19: =B14/B13 -> 0.012112708 | C19: =C14/C13 -> 0.0099322718 | D19: =D14/D13 -> 0.011808312
A20: HET/HOM_ALT ratio | B20: =B16/B17 -> 2.1139631 | C20: =C16/C17 -> 1.7665606 | D20: =D16/D17 -> 2.1884285

Sheet Paired t-test results
A1: Paired t-test comparison of variant-site counts by population and variant class
A2: Population | B2: Sample size (n) | C2: Variant class | D2: Caller comparison | E2: Mean difference (sites; caller 1 − caller 2) | F2: Holm-adjusted p-value | G2: Significant (adjusted p < 0.05)
A3: African | B3: 3 | C3: Common (AF ≥ 0.05) | D3: GATK − DV | E3: -1972.667 | F3: 0.8356823 | G3: No
A4: African | B4: 3 | C4: Common (AF ≥ 0.05) | D4: GATK − DRAGEN | E4: 20108.667 | F4: 0.009462292 | G4: Yes
A5: African | B5: 3 | C5: Common (AF ≥ 0.05) | D5: DV − DRAGEN | E5: 22081.333 | F5: 0.1972776 | G5: No
A6: African | B6: 3 | C6: Rare (0 < AF < 0.01) | D6: GATK − DV | E6: 10986.333 | F6: 0.1500544 | G6: No
A7: African | B7: 3 | C7: Rare (0 < AF < 0.01) | D7: GATK − DRAGEN | E7: 1387.333 | F7: 0.1500544 | G7: No
A8: African | B8: 3 | C8: Rare (0 < AF < 0.01) | D8: DV − DRAGEN | E8: -9599 | F8: 0.1500544 | G8: No
A9: African | B9: 3 | C9: Low-frequency (0.01 ≤ AF < 0.05) | D9: GATK − DV | E9: 9995 | F9: 0.1568309 | G9: No
A10: African | B10: 3 | C10: Low-frequency (0.01 ≤ AF < 0.05) | D10: GATK − DRAGEN | E10: 2386.333 | F10: 0.06394032 | G10: No
A11: African | B11: 3 | C11: Low-frequency (0.01 ≤ AF < 0.05) | D11: DV − DRAGEN | E11: -7608.667 | F11: 0.1568309 | G11: No
A12: African | B12: 3 | C12: Novel (absent from gnomAD) | D12: GATK − DV | E12: -14010 | F12: 0.02843414 | G12: Yes
A13: African | B13: 3 | C13: Novel (absent from gnomAD) | D13: GATK − DRAGEN | E13: 2835 | F13: 0.04716533 | G13: Yes
A14: African | B14: 3 | C14: Novel (absent from gnomAD) | D14: DV − DRAGEN | E14: 16845 | F14: 0.02843414 | G14: Yes
... A38: SAC | B38: 39 | C38: Novel (absent from gnomAD) | D38: DV − DRAGEN | E38: 19426.923 | F38: 2.667037e-27 | G38: Yes

Sheet Summary
A1: Summary of paired t-test results
A3: Population | B3: n | C3: Significant comparisons | D3: Total comparisons
A4: African | B4: 3 | C4: 4 | D4: 12
A5: European | B5: 2 | C5: 0 | D5: 12
A6: SAC | B6: 39 | C6: 12 | D6: 12
A9: Interpretation notes
A10: • Positive mean difference means caller 1 reported more variant sites than caller 2.
A11: • Negative mean difference means caller 2 reported more variant sites than caller 1.
A12: • Novel variants are defined as absent from gnomAD, not by an AF threshold.
A13: • These tests compare caller output counts, not accuracy, sensitivity, or precision.
A14: • African (n=3) and European (n=2) results should be interpreted cautiously due to small sample sizes.
A15: • Frequency classes: common AF ≥ 0.05; rare 0 < AF < 0.01; low-frequency 0.01 ≤ AF < 0.05.
